Workbook

Sheet LuckyJ
A1: # | B1: Date | C1: Rank | D1: Actor | E1: N-Match | F1: N-Rating | G1: N-Bad | H1: H-Match | I1: H-Rating | J1: H-Bad | K1: K-Match | L1: K-Rating | M1: K-Bad | N1: Moves | O1: Players | P1: NAGA Report | Q1: Paifu | S1: Last 10 | T1: Last 10 | U1: Last 10 | V1: Last 20 | W1: Last 20 | X1: Last 20 | Y1: Last 50 | Z1: Last 50 | AA1: Last 50 | AB1: Last 100 | AC1: Last 100 | AD1: Last 100 | AE1: Last 200 | AF1: Last 200 | AG1: Last 200
A2: =IF(B2<>"",ROW()-2,"") -> 0 | B2: 45034.919 | C2: 4 | D2: 0 | E2: 75.471698 | F2: 88.847736 | G2: 9.4339623 | N2: 53 | O2: poona93(+42.2)クマッチ(+5.0)あきまゆともとし(-15.3)ⓝLuckyJ(-31.9) | P2: https://naga.dmv.nico/htmls/015161fe9d8a51ffa77fa23d6cda0ad43998f09e33b0b003d8a1bd24b31d17a6v2_0.html?tw=0 | Q2: https://tenhou.net/4/?log=2023041911gm-0001-0000-cba4cded&tw=0
A3: =IF(B3<>"",ROW()-2,"") -> 1 | B3: 45034.928 | C3: 2 | D3: 3 | E3: 75 | F3: 84.887768 | G3: 10.714286 | H3: 73.214286 | I3: 85.878214 | J3: 8.0357143 | K3: 75 | L3: 84.546786 | M3: 10.714286 | N3: 112 | O3: 心(+54.5)ⓝLuckyJ(+11.3)こうえい(-19.3)牌操作万歳！(-46.5) | P3: https://naga.dmv.nico/htmls/7a24d4ddd9e0d60021075e67ea674c272ebb290b066374752b1fc1d2d3018ffev2_2.html?tw=3 | Q3: https://tenhou.net/4/?log=2023041911gm-0009-0000-24ce7cb7&tw=3 | AH3: Log Avail. | AI3: Total Hanchan
A4: =IF(B4<>"",ROW()-2,"") -> 2 | B4: 45034.947 | C4: 3 | D4: 3 | E4: 69.298246 | F4: 80.862632 | G4: 9.6491228 | H4: 64.035088 | I4: 80.603421 | J4: 9.6491228 | K4: 64.912281 | L4: 74.80614 | M4: 19.298246 | N4: 114 | O4: あれれれれ?(+50.2)NoName(+3.6)ⓝLuckyJ(-19.4)ライオン丸☆彡(-34.4) | P4: https://naga.dmv.nico/htmls/ae812c7aa02889f68a6067c6f9db876cfd1caea3de96f364cc1298e3ab02b2cdv2_2.html?tw=3 | Q4: https://tenhou.net/4/?log=2023041911gm-0009-0000-76965bea&tw=3 | AH4: =COUNTIF(Q3:Q1322,"*tenhou*") -> 1255 | AI4: =COUNTA(Q3:Q1322) -> 1320
A5: =IF(B5<>"",ROW()-2,"") -> 3 | B5: 45034.972 | C5: 2 | D5: 3 | E5: 68.421053 | F5: 80.263421 | G5: 13.157895 | H5: 67.54386 | I5: 83.044035 | J5: 10.526316 | K5: 65.789474 | L5: 78.029298 | M5: 13.157895 | N5: 114 | O5: NoName(+62.7)ⓝLuckyJ(-0.2)ぴーちくぱーちく(-24.8)マシュー(-37.7) | P5: https://naga.dmv.nico/htmls/d00179e866f4a3b86b475eaf72875dd225c121fc3c2af000d74632b57231c1a4v2_2.html?tw=3 | Q5: https://tenhou.net/4/?log=2023041912gm-0009-0000-2fb1c136&tw=3
A6: =IF(B6<>"",ROW()-2,"") -> 4 | B6: 45034.992 | C6: 2 | D6: 3 | E6: 72.321429 | F6: 84.277321 | G6: 11.607143 | H6: 74.107143 | I6: 84.437411 | J6: 6.25 | K6: 73.214286 | L6: 83.267589 | M6: 9.8214286 | N6: 112 | O6: taka432&(+45.0)ⓝLuckyJ(+10.4)rhythm.0(-20.5)おおなり(-34.9) | P6: https://naga.dmv.nico/htmls/b65c8454fc73f6b1da051826ec9113dcc755b99ee5bc96f4f5d9e290733aa912v2_2.html?tw=3 | Q6: https://tenhou.net/4/?log=2023041912gm-0009-0000-9d2b9dfb&tw=3 | AH6: Rank | AJ6: # | AL6: N-Match | AM6: N-Rating | AN6: N-Bad | AO6: H-Match | AP6: H-Rating | AQ6: H-Bad | AR6: K-Match | AS6: K-Rating | AT6: K-Bad
A7: =IF(B7<>"",ROW()-2,"") -> 5 | B7: 45035.015 | C7: 3 | D7: 2 | E7: 78.787879 | F7: 89.565909 | G7: 7.5757576 | H7: 80.30303 | I7: 91.092273 | J7: 7.5757576 | K7: 81.818182 | L7: 91.097576 | M7: 7.5757576 | N7: 66 | O7: pacodel(+66.5)unagi22(+8.5)ⓝLuckyJ(-19.2)Kevin.K(-55.8) | P7: https://naga.dmv.nico/htmls/0b273323e2067d89af605eaa789e7ba65a355f2617fc658c3a7031a7638ffb9ev2_2.html?tw=2 | Q7: https://tenhou.net/4/?log=2023041913gm-0009-0000-481bbd92&tw=2 | AH7: 1 | AI7: =AJ7/SUM(AJ7:AJ10) -> 0.31136364 | AJ7: =COUNTIFS(C3:C1322,1) -> 411 | AL7: =SUMIF($C:$C,1,E:E)/COUNTIFS($C:$C,1,E:E,"<>") -> 74.095741 | AM7: =SUMIF($C:$C,1,F:F)/COUNTIFS($C:$C,1,F:F,"<>") -> 85.821845 | AN7: =SUMIF($C:$C,1,G:G)/COUNTIFS($C:$C,1,G:G,"<>") -> 8.0787295 | AO7: =SUMIF($C:$C,1,H:H)/COUNTIFS($C:$C,1,H:H,"<>") -> 73.00771 | AP7: =SUMIF($C:$C,1,I:I)/COUNTIFS($C:$C,1,I:I,"<>") -> 86.182416 | AQ7: =SUMIF($C:$C,1,J:J)/COUNTIFS($C:$C,1,J:J,"<>") -> 7.1789354 | AR7: =SUMIF($C:$C,1,K:K)/COUNTIFS($C:$C,1,K:K,"<>") -> 72.452777 | AS7: =SUMIF($C:$C,1,L:L)/COUNTIFS($C:$C,1,L:L,"<>") -> 84.609945 | AT7: =SUMIF($C:$C,1,M:M)/COUNTIFS($C:$C,1,M:M,"<>") -> 9.3569107
A8: =IF(B8<>"",ROW()-2,"") -> 6 | B8: 45035.027 | C8: 1 | D8: 1 | E8: 88.607595 | F8: 93.363418 | G8: 6.3291139 | H8: 82.278481 | I8: 89.697848 | J8: 3.7974684 | K8: 86.075949 | L8: 91.756076 | M8: 5.0632911 | N8: 79 | O8: ⓝLuckyJ(+63.6)NoName(+9.6)小さな愛は(-14.5)タケとシルバ(-58.7) | P8: https://naga.dmv.nico/htmls/13fc5d471b8821ec227703a14aa9b12d2aca8eb5fe3076624fd959a3ac3fc7b0v2_2.html?tw=1 | Q8: https://tenhou.net/4/?log=2023041913gm-0009-0000-95da9e3b&tw=1 | AH8: 2 | AI8: =AJ8/SUM(AJ7:AJ10) -> 0.27348485 | AJ8: =COUNTIFS(C3:C1322,2) -> 361 | AL8: =SUMIF($C:$C,2,E:E)/COUNTIFS($C:$C,2,E:E,"<>") -> 73.495242 | AM8: =SUMIF($C:$C,2,F:F)/COUNTIFS($C:$C,2,F:F,"<>") -> 85.28645 | AN8: =SUMIF($C:$C,2,G:G)/COUNTIFS($C:$C,2,G:G,"<>") -> 8.2471158 | AO8: =SUMIF($C:$C,2,H:H)/COUNTIFS($C:$C,2,H:H,"<>") -> 72.770345 | AP8: =SUMIF($C:$C,2,I:I)/COUNTIFS($C:$C,2,I:I,"<>") -> 85.99148 | AQ8: =SUMIF($C:$C,2,J:J)/COUNTIFS($C:$C,2,J:J,"<>") -> 7.3259551 | AR8: =SUMIF($C:$C,2,K:K)/COUNTIFS($C:$C,2,K:K,"<>") -> 71.995634 | AS8: =SUMIF($C:$C,2,L:L)/COUNTIFS($C:$C,2,L:L,"<>") -> 83.994215 | AT8: =SUMIF($C:$C,2,M:M)/COUNTIFS($C:$C,2,M:M,"<>") -> 9.5057154
A9: =IF(B9<>"",ROW()-2,"") -> 7 | B9: 45035.042 | C9: 3 | D9: 1 | E9: 75.735294 | F9: 85.224559 | G9: 8.8235294 | H9: 69.852941 | I9: 83.391618 | J9: 10.294118 | K9: 75.735294 | L9: 84.391544 | M9: 10.294118 | N9: 136 | O9: 九蓮宝燈やりたい(+52.0)JPNOGAWA(+19.4)ⓝLuckyJ(-18.9)kaboom(-52.5) | P9: https://naga.dmv.nico/htmls/9b3ecbfc6986ebe6fc3e585013ae0b5a5d3390e71bab778480b3cbe042019506v2_2.html?tw=1 | Q9: https://tenhou.net/4/?log=2023041914gm-0009-0000-02f8c9e2&tw=1 | AH9: 3 | AI9: =AJ9/SUM(AJ7:AJ10) -> 0.2530303 | AJ9: =COUNTIFS(C3:C1322,3) -> 334 | AL9: =SUMIF($C:$C,3,E:E)/COUNTIFS($C:$C,3,E:E,"<>") -> 74.073373 | AM9: =SUMIF($C:$C,3,F:F)/COUNTIFS($C:$C,3,F:F,"<>") -> 85.648444 | AN9: =SUMIF($C:$C,3,G:G)/COUNTIFS($C:$C,3,G:G,"<>") -> 7.9534085 | AO9: =SUMIF($C:$C,3,H:H)/COUNTIFS($C:$C,3,H:H,"<>") -> 73.174828 | AP9: =SUMIF($C:$C,3,I:I)/COUNTIFS($C:$C,3,I:I,"<>") -> 86.073501 | AQ9: =SUMIF($C:$C,3,J:J)/COUNTIFS($C:$C,3,J:J,"<>") -> 7.2068741 | AR9: =SUMIF($C:$C,3,K:K)/COUNTIFS($C:$C,3,K:K,"<>") -> 72.379561 | AS9: =SUMIF($C:$C,3,L:L)/COUNTIFS($C:$C,3,L:L,"<>") -> 84.379802 | AT9: =SUMIF($C:$C,3,M:M)/COUNTIFS($C:$C,3,M:M,"<>") -> 9.1763778
A10: =IF(B10<>"",ROW()-2,"") -> 8 | B10: 45035.062 | C10: 3 | D10: 0 | E10: 68.478261 | F10: 81.76337 | G10: 4.3478261 | H10: 71.73913 | I10: 86.531304 | J10: 3.2608696 | K10: 69.565217 | L10: 82.890109 | M10: 9.7826087 | N10: 92 | O10: sannpuru(+56.0)GGB(+19.5)ⓝLuckyJ(-26.2)ichik(-49.3) | P10: https://naga.dmv.nico/htmls/91789d99d86ef1f4ba0a0ec23841833799d72072b031e8503687673b4df2d037v2_2.html?tw=0 | Q10: https://tenhou.net/4/?log=2023041914gm-0009-0000-f04c7ced&tw=0 | AH10: 4 | AI10: =AJ10/SUM(AJ7:AJ10) -> 0.16212121 | AJ10: =COUNTIFS(C3:C1322,4) -> 214 | AL10: =SUMIF($C:$C,4,E:E)/COUNTIFS($C:$C,4,E:E,"<>") -> 74.558168 | AM10: =SUMIF($C:$C,4,F:F)/COUNTIFS($C:$C,4,F:F,"<>") -> 85.808273 | AN10: =SUMIF($C:$C,4,G:G)/COUNTIFS($C:$C,4,G:G,"<>") -> 8.1062306 | AO10: =SUMIF($C:$C,4,H:H)/COUNTIFS($C:$C,4,H:H,"<>") -> 73.632327 | AP10: =SUMIF($C:$C,4,I:I)/COUNTIFS($C:$C,4,I:I,"<>") -> 86.166666 | AQ10: =SUMIF($C:$C,4,J:J)/COUNTIFS($C:$C,4,J:J,"<>") -> 7.0616088 | AR10: =SUMIF($C:$C,4,K:K)/COUNTIFS($C:$C,4,K:K,"<>") -> 72.888429 | AS10: =SUMIF($C:$C,4,L:L)/COUNTIFS($C:$C,4,L:L,"<>") -> 84.557659 | AT10: =SUMIF($C:$C,4,M:M)/COUNTIFS($C:$C,4,M:M,"<>") -> 9.230332
A11: =IF(B11<>"",ROW()-2,"") -> 9 | B11: 45035.08 | C11: 1 | D11: 0 | E11: 68.041237 | F11: 83.895052 | G11: 11.340206 | H11: 73.195876 | I11: 86.319072 | J11: 6.185567 | K11: 65.979381 | L11: 80.650309 | M11: 11.340206 | N11: 97 | O11: ⓝLuckyJ(+51.2)コムギ丸(+7.1)クsoge-クン(-18.0)rensou(-40.3) | P11: https://naga.dmv.nico/htmls/a08608701506356f3c0dee3f3e1c4f130ef102925a9b27f12b5a288077a03106v2_2.html?tw=0 | Q11: https://tenhou.net/4/?log=2023041914gm-0009-0000-905aedb2&tw=0
A12: =IF(B12<>"",ROW()-2,"") -> 10 | B12: 45035.094 | C12: 2 | D12: 0 | E12: 69.230769 | F12: 85.134701 | G12: 8.5470085 | H12: 67.521368 | I12: 82.602137 | J12: 10.25641 | K12: 70.940171 | L12: 82.734786 | M12: 8.5470085 | N12: 117 | O12: タケとシルバ(+41.9)ⓝLuckyJ(+6.9)あぱぱぱ(-18.5)ポチこん(-30.3) | P12: https://naga.dmv.nico/htmls/ae5cfcb0dc30450732306bc696644a22ebdef7e6e68e62073ea3016f9963621av2_2.html?tw=0 | Q12: https://tenhou.net/4/?log=2023041915gm-0009-0000-d2489ac6&tw=0 | S12: =IF(E12="","",AVERAGE(E3:E12)) -> 73.392176 | T12: =IF(F12="","",AVERAGE(F3:F12)) -> 84.923815 | U12: =IF(G12="","",AVERAGE(G3:G12)) -> 9.2091888 | AH12: Player | AI12: ⓝLuckyJ | AL12: -first tonpuu game excluded from stats
A13: =IF(B13<>"",ROW()-2,"") -> 11 | B13: 45035.114 | C13: 2 | D13: 2 | E13: 61.73913 | F13: 80.877391 | G13: 11.304348 | H13: 51.304348 | I13: 79.342435 | J13: 13.043478 | K13: 55.652174 | L13: 74.918783 | M13: 14.782609 | N13: 115 | O13: ayappe(+45.9)ⓝLuckyJ(+11.7)トルコ桔梗(-19.4)NoName(-38.2) | P13: https://naga.dmv.nico/htmls/6b5e8ff0c6d86538bad357fc6b212303578afef437b080945b07aecbea734c83v2_2.html?tw=2 | Q13: https://tenhou.net/4/?log=2023041915gm-0009-0000-72f6b798&tw=2 | S13: =IF(E13="","",AVERAGE(E4:E13)) -> 72.066089 | T13: =IF(F13="","",AVERAGE(F4:F13)) -> 84.522777 | U13: =IF(G13="","",AVERAGE(G4:G13)) -> 9.268195 | AH13: Avg Rank | AI13: =(1*AJ7+2*AJ8+3*AJ9+4*AJ10)/SUM(AJ7:AJ10) -> 2.2659091 | AL13: https://nodocchi.moe/tenhoulog/index.html#!&name=%E2%93%9DLuckyJ
A14: =IF(B14<>"",ROW()-2,"") -> 12 | B14: 45035.144 | C14: 1 | D14: 1 | E14: 78.75 | F14: 89.584875 | G14: 6.25 | H14: 81.25 | I14: 90.85275 | J14: 2.5 | K14: 81.25 | L14: 87.524375 | M14: 8.75 | N14: 80 | O14: ⓝLuckyJ(+73.7)NoName(-0.8)N0name(-21.2)よこやま(-51.7) | P14: https://naga.dmv.nico/htmls/82fc7e40253c3a445280ed5ca3da14b8bb85ad110826f192505a54be6b6ec3c0v2_2.html?tw=1 | Q14: https://tenhou.net/4/?log=2023041916gm-0009-0000-2147738b&tw=1 | S14: =IF(E14="","",AVERAGE(E5:E14)) -> 73.011265 | T14: =IF(F14="","",AVERAGE(F5:F14)) -> 85.395002 | U14: =IF(G14="","",AVERAGE(G5:G14)) -> 8.9282827 | AH14: Games | AI14: =SUM(AJ7:AJ10) -> 1320
A15: =IF(B15<>"",ROW()-2,"") -> 13 | B15: 45035.162 | C15: 2 | D15: 3 | E15: 73.333333 | F15: 86.715333 | G15: 6.6666667 | H15: 72 | I15: 87.176267 | J15: 7.3333333 | K15: 73.333333 | L15: 84.9796 | M15: 7.3333333 | N15: 150 | O15: EN2023(+48.5)ⓝLuckyJ(+10.5)yuki2965(-20.4)はなさかじいさん(-38.6) | P15: https://naga.dmv.nico/htmls/9ce8429f01389974e550dc5402e45d1f8c231b761c775d8399264a7cc00e8082v2_2.html?tw=3 | Q15: https://tenhou.net/4/?log=2023041916gm-0009-0000-3551c4d5&tw=3 | S15: =IF(E15="","",AVERAGE(E6:E15)) -> 73.502493 | T15: =IF(F15="","",AVERAGE(F6:F15)) -> 86.040193 | U15: =IF(G15="","",AVERAGE(G6:G15)) -> 8.2791599 | AH15: Progress | AI15: =COUNTIF(P3:P1322,"*naga*") -> 1255 | AL15: Lowest | AM15: Highest | AO15: Month | AP15: 45047 | AQ15: 45017
A16: =IF(B16<>"",ROW()-2,"") -> 14 | B16: 45035.193 | C16: 3 | D16: 0 | E16: 70.79646 | F16: 83.769735 | G16: 10.619469 | H16: 73.451327 | I16: 84.537522 | J16: 7.079646 | K16: 74.336283 | L16: 86.249381 | M16: 7.9646018 | N16: 113 | O16: 宝くじ７(+75.7)麻雀脳(+0.1)ⓝLuckyJ(-25.4)北村方向(-50.4) | P16: https://naga.dmv.nico/htmls/fb57745407c9d72db76a664e53dafccff0d22a1b2110b3617e98e924ac44869av2_2.html?tw=0 | Q16: https://tenhou.net/4/?log=2023041917gm-0009-0000-258c559e&tw=0 | S16: =IF(E16="","",AVERAGE(E7:E16)) -> 73.349996 | T16: =IF(F16="","",AVERAGE(F7:F16)) -> 85.989434 | U16: =IF(G16="","",AVERAGE(G7:G16)) -> 8.1803925 | AH16: Avg N-Match | AI16: =AVERAGE(E:E) -> 74.001617 | AL16: =min(E:E) -> 52 | AM16: =max(E:E) -> 97.5 | AO16: N-Rating | AP16: =AVERAGEIFS($F3:$F1322,$B3:$B1322,">="&AP15,$B3:$B1322,"<"&(EOMONTH(AP15,0)+1)) -> 85.721689 | AQ16: =AVERAGEIFS($F3:$F1322,$B3:$B1322,">="&AQ15,$B3:$B1322,"<"&(EOMONTH(AQ15,0)+1)) -> 85.400892
A17: =IF(B17<>"",ROW()-2,"") -> 15 | B17: 45035.212 | C17: 1 | D17: 1 | E17: 81.355932 | F17: 87.304576 | G17: 5.0847458 | H17: 77.966102 | I17: 87.012542 | J17: 6.779661 | K17: 72.881356 | L17: 86.025932 | M17: 8.4745763 | N17: 59 | O17: ⓝLuckyJ(+47.7)ウエスタンT.C(+15.2)－えむわい－(-12.1)MOMONT(-50.8) | P17: https://naga.dmv.nico/htmls/0c82f956dd28beec439d61b25acfcaa56d2e65515bbd9d5fa6a17242f0962461v2_2.html?tw=1 | Q17: https://tenhou.net/4/?log=2023041918gm-0009-0000-63986359&tw=1 | S17: =IF(E17="","",AVERAGE(E8:E17)) -> 73.606801 | T17: =IF(F17="","",AVERAGE(F8:F17)) -> 85.763301 | U17: =IF(G17="","",AVERAGE(G8:G17)) -> 7.9312913 | AH17: Avg N-Rating | AI17: =AVERAGE(F:F) -> 85.629931 | AL17: =min(F:F) -> 72.414091 | AM17: =max(F:F) -> 99.53525 | AO17: N-Bad % | AP17: =AVERAGEIFS($G3:$G1322,$B3:$B1322,">="&AP15,$B3:$B1322,"<"&(EOMONTH(AP15,0)+1)) -> 8.0505452 | AQ17: =AVERAGEIFS($G3:$G1322,$B3:$B1322,">="&AQ15,$B3:$B1322,"<"&(EOMONTH(AQ15,0)+1)) -> 8.2075483
A18: =IF(B18<>"",ROW()-2,"") -> 16 | B18: 45035.224 | C18: 2 | D18: 3 | E18: 68.253968 | F18: 86.67754 | G18: 7.1428571 | H18: 69.84127 | I18: 85.891825 | J18: 11.111111 | K18: 62.698413 | L18: 83.670952 | M18: 7.9365079 | N18: 126 | O18: コントレイル常(+41.9)ⓝLuckyJ(+10.7)NoName(-20.7)yama79(-31.9) | P18: https://naga.dmv.nico/htmls/4de88a2f7ec4fcc76ecf9f93e8a0a7f63245a676646e9f73dbb40241b9cd7d87v2_2.html?tw=3 | Q18: https://tenhou.net/4/?log=2023041918gm-0009-0000-99286749&tw=3 | S18: =IF(E18="","",AVERAGE(E9:E18)) -> 71.571439 | T18: =IF(F18="","",AVERAGE(F9:F18)) -> 85.094713 | U18: =IF(G18="","",AVERAGE(G9:G18)) -> 8.0126657 | AH18: Avg N-Bad | AI18: =AVERAGE(G:G) -> 8.0977726 | AL18: =min(G:G) -> 0 | AM18: =max(G:G) -> 21.428571 | AO18: Games | AP18: =COUNTIFS($B3:$B1322,">="&AP15,$B3:$B1322,"<"&(EOMONTH(AP15,0)+1)) -> 935 | AQ18: =COUNTIFS($B3:$B1322,">="&AQ15,$B3:$B1322,"<"&(EOMONTH(AQ15,0)+1)) -> 385
A19: =IF(B19<>"",ROW()-2,"") -> 17 | B19: 45035.251 | C19: 2 | D19: 2 | E19: 64.583333 | F19: 84.645417 | G19: 8.3333333 | H19: 66.666667 | I19: 85.575 | J19: 4.1666667 | K19: 66.666667 | L19: 80.847708 | M19: 10.416667 | N19: 48 | O19: 上埜久(+63.5)ⓝLuckyJ(+9.0)NoName(-22.2)juck(-50.3) | P19: https://naga.dmv.nico/htmls/b7e227eaeca10df1519afb8f10c7457658d16819f7a80bc0fce0420a8dbd1706v2_2.html?tw=2 | Q19: https://tenhou.net/4/?log=2023041919gm-0009-0000-ebacd917&tw=2 | S19: =IF(E19="","",AVERAGE(E10:E19)) -> 70.456242 | T19: =IF(F19="","",AVERAGE(F10:F19)) -> 85.036799 | U19: =IF(G19="","",AVERAGE(G10:G19)) -> 7.9636461 | AH19: Avg H-Match | AI19: =AVERAGE(H:H) -> 73.086314 | AL19: =min(H:H) -> 50 | AM19: =max(H:H) -> 92.5
A20: =IF(B20<>"",ROW()-2,"") -> 18 | B20: 45035.262 | C20: 3 | D20: 2 | E20: 68.468468 | F20: 84.227027 | G20: 6.3063063 | H20: 72.972973 | I20: 85.373964 | J20: 5.4054054 | K20: 76.576577 | L20: 86.115315 | M20: 6.3063063 | N20: 111 | O20: 雀魂やめました(+69.8)yasuNORI(+5.7)ⓝLuckyJ(-14.4)玉次郎(-61.1) | P20: https://naga.dmv.nico/htmls/a55c5b745d198c1586c8eb377f0341236974d5051af4d495383042e486823394v2_2.html?tw=2 | Q20: https://tenhou.net/4/?log=2023041919gm-0009-0000-3a6c978b&tw=2 | S20: =IF(E20="","",AVERAGE(E11:E20)) -> 70.455263 | T20: =IF(F20="","",AVERAGE(F11:F20)) -> 85.283165 | U20: =IF(G20="","",AVERAGE(G11:G20)) -> 8.1594941 | AH20: Avg H-Rating | AI20: =AVERAGE(I:I) -> 86.100335 | AL20: =min(I:I) -> 74.44303 | AM20: =max(I:I) -> 98.369
A21: =IF(B21<>"",ROW()-2,"") -> 19 | B21: 45035.285 | C21: 1 | D21: 2 | E21: 72.641509 | F21: 84.040472 | G21: 9.4339623 | H21: 68.867925 | I21: 84.591321 | J21: 7.5471698 | K21: 66.981132 | L21: 81.892264 | M21: 10.377358 | N21: 106 | O21: ⓝLuckyJ(+66.0)M-KAMADA(+1.7)モロブラン(-24.8)smoker33(-42.9) | P21: https://naga.dmv.nico/htmls/3edec3119773a7d5ec6d6ef1d43eb0c2be7d1ef1ade12aa06741e09c6b142be1v2_2.html?tw=2 | Q21: https://tenhou.net/4/?log=2023041919gm-0009-0000-1f370ff0&tw=2 | S21: =IF(E21="","",AVERAGE(E12:E21)) -> 70.91529 | T21: =IF(F21="","",AVERAGE(F12:F21)) -> 85.297707 | U21: =IF(G21="","",AVERAGE(G12:G21)) -> 7.9688697 | AH21: Avg H-Bad | AI21: =AVERAGE(J:J) -> 7.207058 | AL21: =min(J:J) -> 0 | AM21: =max(J:J) -> 20
A22: =IF(B22<>"",ROW()-2,"") -> 20 | B22: 45035.305 | C22: 3 | D22: 1 | E22: 62.820513 | F22: 80.500256 | G22: 11.538462 | H22: 64.102564 | I22: 81.015385 | J22: 7.6923077 | K22: 57.692308 | L22: 76.922564 | M22: 11.538462 | N22: 78 | O22: kawabe(+58.1)COMSL(+20.0)ⓝLuckyJ(-25.4)kiku2361(-52.7) | P22: https://naga.dmv.nico/htmls/32af865e65d255b3ab97c1f7315b898a899d27c3b3d6cefb65317aad25d7ede9v2_2.html?tw=1 | Q22: https://tenhou.net/4/?log=2023041920gm-0009-0000-2e91f650&tw=1 | S22: =IF(E22="","",AVERAGE(E13:E22)) -> 70.274265 | T22: =IF(F22="","",AVERAGE(F13:F22)) -> 84.834262 | U22: =IF(G22="","",AVERAGE(G13:G22)) -> 8.268015 | V22: =IF(E22="","",AVERAGE(E3:E22)) -> 71.833221 | W22: =IF(F22="","",AVERAGE(F3:F22)) -> 84.879039 | X22: =IF(G22="","",AVERAGE(G3:G22)) -> 8.7386019 | AH22: Avg K-Match | AI22: =AVERAGE(K:K) -> 72.380275 | AL22: =min(K:K) -> 52.272727 | AM22: =max(K:K) -> 97.5
A23: =IF(B23<>"",ROW()-2,"") -> 21 | B23: 45035.319 | C23: 4 | D23: 1 | E23: 79.439252 | F23: 88.72028 | G23: 5.6074766 | H23: 82.242991 | I23: 88.877757 | J23: 5.6074766 | K23: 78.504673 | L23: 86.90514 | M23: 5.6074766 | N23: 107 | O23: こすず(+55.3)きのみぃ(+4.2)残飯くん(-20.6)ⓝLuckyJ(-38.9) | P23: https://naga.dmv.nico/htmls/80f871d582a45302e3c399b4e60ba9308bfefb869ebfc55d827cdfc0695651dfv2_2.html?tw=1 | Q23: https://tenhou.net/4/?log=2023041920gm-0009-0000-1e13a6a6&tw=1 | S23: =IF(E23="","",AVERAGE(E14:E23)) -> 72.044277 | T23: =IF(F23="","",AVERAGE(F14:F23)) -> 85.618551 | U23: =IF(G23="","",AVERAGE(G14:G23)) -> 7.6983279 | V23: =IF(E23="","",AVERAGE(E4:E23)) -> 72.055183 | W23: =IF(F23="","",AVERAGE(F4:F23)) -> 85.070664 | X23: =IF(G23="","",AVERAGE(G4:G23)) -> 8.4832614 | AH23: Avg K-Rating | AI23: =AVERAGE(L:L) -> 84.375398 | AL23: =min(L:L) -> 70.806136 | AM23: =max(L:L) -> 98.92525
A24: =IF(B24<>"",ROW()-2,"") -> 22 | B24: 45035.341 | C24: 1 | D24: 1 | E24: 77.777778 | F24: 85.03127 | G24: 12.698413 | H24: 73.015873 | I24: 84.198889 | J24: 11.111111 | K24: 74.603175 | L24: 82.892063 | M24: 12.698413 | N24: 63 | O24: ⓝLuckyJ(+53.1)RIOSUBA(+11.1)アッティバティ(-12.4)NIAGARA(-51.8) | P24: https://naga.dmv.nico/htmls/7f89121448a35f7f5512b48f8c348c1fcfdefd8a6daed41ee2897ace2a853dbfv2_2.html?tw=1 | Q24: https://tenhou.net/4/?log=2023041921gm-0009-0000-5c860451&tw=1 | S24: =IF(E24="","",AVERAGE(E15:E24)) -> 71.947055 | T24: =IF(F24="","",AVERAGE(F15:F24)) -> 85.163191 | U24: =IF(G24="","",AVERAGE(G15:G24)) -> 8.3431691 | V24: =IF(E24="","",AVERAGE(E5:E24)) -> 72.47916 | W24: =IF(F24="","",AVERAGE(F5:F24)) -> 85.279096 | X24: =IF(G24="","",AVERAGE(G5:G24)) -> 8.6357259 | AH24: Avg K-Bad | AI24: =AVERAGE(M:M) -> 9.3316916 | AL24: =min(M:M) -> 0 | AM24: =max(M:M) -> 20.454545
A25: =IF(B25<>"",ROW()-2,"") -> 23 | B25: 45035.352 | C25: 2 | D25: 3 | E25: 68.292683 | F25: 81.072439 | G25: 11.382114 | H25: 70.731707 | I25: 85.871057 | J25: 6.504065 | K25: 69.918699 | L25: 83.763984 | M25: 8.1300813 | N25: 123 | O25: Cheeeee(+57.3)ⓝLuckyJ(+3.5)TOMOKEN(-22.0)swimcap(-38.8) | P25: https://naga.dmv.nico/htmls/e1054a708cd5ccaf98803bc57d7061c2d67e6b059b4f9092fed19411ea350f3ev2_2.html?tw=3 | Q25: https://tenhou.net/4/?log=2023041921gm-0009-0000-47d50d35&tw=3 | S25: =IF(E25="","",AVERAGE(E16:E25)) -> 71.44299 | T25: =IF(F25="","",AVERAGE(F16:F25)) -> 84.598901 | U25: =IF(G25="","",AVERAGE(G16:G25)) -> 8.8147139 | V25: =IF(E25="","",AVERAGE(E6:E25)) -> 72.472741 | W25: =IF(F25="","",AVERAGE(F6:F25)) -> 85.319547 | X25: =IF(G25="","",AVERAGE(G6:G25)) -> 8.5469369 | AH25: Avg Moves | AI25: =AVERAGE(N:N) -> 117.33917 | AL25: =min(N:N) -> 9 | AM25: =max(N:N) -> 255
A26: =IF(B26<>"",ROW()-2,"") -> 24 | B26: 45035.376 | C26: 1 | D26: 0 | E26: 69.827586 | F26: 83.537759 | G26: 10.344828 | H26: 75.862069 | I26: 87.101897 | J26: 9.4827586 | K26: 70.689655 | L26: 82.362931 | M26: 12.931034 | N26: 116 | O26: ⓝLuckyJ(+48.9)夜のピエロ(+10.8)李秀明明(-16.2)NoName(-43.5) | P26: https://naga.dmv.nico/htmls/589876618f35a6bfd9890de77f30b2776cf0c9ae1c0004d2e51ba9e194bbc01cv2_2.html?tw=0 | Q26: https://tenhou.net/4/?log=2023041922gm-0009-0000-1d429576&tw=0 | S26: =IF(E26="","",AVERAGE(E17:E26)) -> 71.346102 | T26: =IF(F26="","",AVERAGE(F17:F26)) -> 84.575704 | U26: =IF(G26="","",AVERAGE(G17:G26)) -> 8.7872497 | V26: =IF(E26="","",AVERAGE(E7:E26)) -> 72.348049 | W26: =IF(F26="","",AVERAGE(F7:F26)) -> 85.282569 | X26: =IF(G26="","",AVERAGE(G7:G26)) -> 8.4838211
A27: =IF(B27<>"",ROW()-2,"") -> 25 | B27: 45035.398 | C27: 1 | D27: 2 | E27: 76.470588 | F27: 86.379926 | G27: 7.3529412 | H27: 75.735294 | I27: 85.763603 | J27: 7.3529412 | K27: 69.852941 | L27: 83.191544 | M27: 12.5 | N27: 136 | O27: ⓝLuckyJ(+48.6)ひさQ(+7.9)コミヤマサン(-13.9)NoName(-42.6) | P27: https://naga.dmv.nico/htmls/a35070b9062590c90af5ba0700f1160b3afd5b307477a05a0626621d5688d83fv2_2.html?tw=2 | Q27: https://tenhou.net/4/?log=2023041922gm-0009-0000-6def000f&tw=2 | S27: =IF(E27="","",AVERAGE(E18:E27)) -> 70.857568 | T27: =IF(F27="","",AVERAGE(F18:F27)) -> 84.483239 | U27: =IF(G27="","",AVERAGE(G18:G27)) -> 9.0140693 | V27: =IF(E27="","",AVERAGE(E8:E27)) -> 72.232185 | W27: =IF(F27="","",AVERAGE(F8:F27)) -> 85.12327 | X27: =IF(G27="","",AVERAGE(G8:G27)) -> 8.4726803
A28: =IF(B28<>"",ROW()-2,"") -> 26 | B28: 45035.422 | C28: 4 | D28: 1 | E28: 68.367347 | F28: 82.897653 | G28: 5.1020408 | H28: 65.306122 | I28: 82.860408 | J28: 6.122449 | K28: 63.265306 | L28: 81.084592 | M28: 13.265306 | N28: 98 | O28: ミツオ(+65.4)愛舞モコ(+10.8)abc5111(-32.2)ⓝLuckyJ(-44.0) | P28: https://naga.dmv.nico/htmls/f03d1e1bb536f4f1abe6bcc4defdab050558c1d21875dd172438dc78b245db2av2_2.html?tw=1 | Q28: https://tenhou.net/4/?log=2023041923gm-0009-0000-029075c2&tw=1 | S28: =IF(E28="","",AVERAGE(E19:E28)) -> 70.868906 | T28: =IF(F28="","",AVERAGE(F19:F28)) -> 84.10525 | U28: =IF(G28="","",AVERAGE(G19:G28)) -> 8.8099876 | V28: =IF(E28="","",AVERAGE(E9:E28)) -> 71.220172 | W28: =IF(F28="","",AVERAGE(F9:F28)) -> 84.599981 | X28: =IF(G28="","",AVERAGE(G9:G28)) -> 8.4113266
A29: =IF(B29<>"",ROW()-2,"") -> 27 | B29: 45035.44 | C29: 3 | D29: 1 | E29: 76.146789 | F29: 85.597706 | G29: 6.4220183 | H29: 76.146789 | I29: 87.613853 | J29: 5.5045872 | K29: 67.889908 | L29: 80.109358 | M29: 8.2568807 | N29: 109 | O29: cx1122(+46.6)まるまる(+8.0)ⓝLuckyJ(-16.8)rosso(-37.8) | P29: https://naga.dmv.nico/htmls/3f29e82abdc3a085c1e5f70e8edb15f5b3adbd044ee6f6879e29ccd6a11e653bv2_2.html?tw=1 | Q29: https://tenhou.net/4/?log=2023041923gm-0009-0000-73949e90&tw=1 | S29: =IF(E29="","",AVERAGE(E20:E29)) -> 72.025251 | T29: =IF(F29="","",AVERAGE(F20:F29)) -> 84.200479 | U29: =IF(G29="","",AVERAGE(G20:G29)) -> 8.6188561 | V29: =IF(E29="","",AVERAGE(E10:E29)) -> 71.240747 | W29: =IF(F29="","",AVERAGE(F10:F29)) -> 84.618639 | X29: =IF(G29="","",AVERAGE(G10:G29)) -> 8.2912511
A30: =IF(B30<>"",ROW()-2,"") -> 28 | B30: 45035.461 | C30: 4 | D30: 0 | E30: 82.051282 | F30: 89.34265 | G30: 6.8376068 | H30: 83.760684 | I30: 89.13812 | J30: 7.6923077 | K30: 81.196581 | L30: 89.471111 | M30: 7.6923077 | N30: 117 | O30: サラズ(+41.0)Iolon(+9.6)冷やしタヌキ(-11.1)ⓝLuckyJ(-39.5) | P30: https://naga.dmv.nico/htmls/734550f19ae8e10d80a10a4d0bd85d0282074af0485ce042175e47a6788743d9v2_2.html?tw=0 | Q30: https://tenhou.net/4/?log=2023042000gm-0009-0000-544d3398&tw=0 | S30: =IF(E30="","",AVERAGE(E21:E30)) -> 73.383533 | T30: =IF(F30="","",AVERAGE(F21:F30)) -> 84.712041 | U30: =IF(G30="","",AVERAGE(G21:G30)) -> 8.6719862 | V30: =IF(E30="","",AVERAGE(E11:E30)) -> 71.919398 | W30: =IF(F30="","",AVERAGE(F11:F30)) -> 84.997603 | X30: =IF(G30="","",AVERAGE(G11:G30)) -> 8.4157401
A31: =IF(B31<>"",ROW()-2,"") -> 29 | B31: 45035.485 | C31: 1 | D31: 0 | E31: 69.166667 | F31: 83.378667 | G31: 10 | H31: 73.333333 | I31: 87.0645 | J31: 7.5 | K31: 75.833333 | L31: 85.570083 | M31: 11.666667 | N31: 120 | O31: ⓝLuckyJ(+66.0)部長直属の３人目(+6.6)サラズ(-26.6)DRK(-46.0) | P31: https://naga.dmv.nico/htmls/b1e1fedd4c0c1ca314fabc79144ce2e8da0ef247a37e2ce08518a56a2c20626bv2_2.html?tw=0 | Q31: https://tenhou.net/4/?log=2023042000gm-0009-0000-4aeb94c4&tw=0 | S31: =IF(E31="","",AVERAGE(E22:E31)) -> 73.036049 | T31: =IF(F31="","",AVERAGE(F22:F31)) -> 84.645861 | U31: =IF(G31="","",AVERAGE(G22:G31)) -> 8.7285899 | V31: =IF(E31="","",AVERAGE(E12:E31)) -> 71.975669 | W31: =IF(F31="","",AVERAGE(F12:F31)) -> 84.971784 | X31: =IF(G31="","",AVERAGE(G12:G31)) -> 8.3487298
A32: =IF(B32<>"",ROW()-2,"") -> 30 | B32: 45035.504 | C32: 3 | D32: 3 | E32: 65.734266 | F32: 82.758951 | G32: 11.188811 | H32: 71.328671 | I32: 84.613287 | J32: 9.7902098 | K32: 69.93007 | L32: 81.494126 | M32: 11.888112 | N32: 143 | O32: 山本こうや(+48.2)SFGiants(+6.7)ⓝLuckyJ(-20.2)koshiko(-34.7) | P32: https://naga.dmv.nico/htmls/090c6ac8ad82466140a60f6d5f89d4a1426eb9de8c9be9a6270e3e7e356fe68dv2_2.html?tw=3 | Q32: https://tenhou.net/4/?log=2023042001gm-0009-0000-333a7cb8&tw=3 | S32: =IF(E32="","",AVERAGE(E23:E32)) -> 73.327424 | T32: =IF(F32="","",AVERAGE(F23:F32)) -> 84.87173 | U32: =IF(G32="","",AVERAGE(G23:G32)) -> 8.6936249 | V32: =IF(E32="","",AVERAGE(E13:E32)) -> 71.800844 | W32: =IF(F32="","",AVERAGE(F13:F32)) -> 84.852996 | X32: =IF(G32="","",AVERAGE(G13:G32)) -> 8.4808199
A33: =IF(B33<>"",ROW()-2,"") -> 31 | B33: 45035.863 | C33: 1 | D33: 2 | E33: 72.815534 | F33: 84.808835 | G33: 6.7961165 | H33: 71.84466 | I33: 83.248447 | J33: 10.679612 | K33: 69.902913 | L33: 83.231068 | M33: 7.7669903 | N33: 103 | O33: ⓝLuckyJ(+44.2)いとおやじ92(+9.6)のぶ１７５１(-14.9)Ο(-38.9) | P33: https://naga.dmv.nico/htmls/04d47849b81c37c3a58c0c664fb52b2eef4c645b12ac81bdf57dd66b9e909a53v2_2.html?tw=2 | Q33: https://tenhou.net/4/?log=2023042009gm-0009-0000-3e6354b7&tw=2 | S33: =IF(E33="","",AVERAGE(E24:E33)) -> 72.665052 | T33: =IF(F33="","",AVERAGE(F24:F33)) -> 84.480586 | U33: =IF(G33="","",AVERAGE(G24:G33)) -> 8.8124889 | V33: =IF(E33="","",AVERAGE(E14:E33)) -> 72.354664 | W33: =IF(F33="","",AVERAGE(F14:F33)) -> 85.049568 | X33: =IF(G33="","",AVERAGE(G14:G33)) -> 8.2554084
A34: =IF(B34<>"",ROW()-2,"") -> 32 | B34: 45035.88 | C34: 3 | D34: 2 | E34: 79.439252 | F34: 87.971402 | G34: 6.5420561 | H34: 76.635514 | I34: 86.288505 | J34: 6.5420561 | K34: 74.766355 | L34: 84.574019 | M34: 9.3457944 | N34: 107 | O34: 0610(+48.1)jun6696(+13.5)ⓝLuckyJ(-17.1)わびわび(-44.5) | P34: https://naga.dmv.nico/htmls/a201257b7589d7121ec37ab94e62b44f9431a34bc0501657e51ac9d9c16a6957v2_2.html?tw=2 | Q34: https://tenhou.net/4/?log=2023042010gm-0009-0000-aa278fc2&tw=2 | S34: =IF(E34="","",AVERAGE(E25:E34)) -> 72.831199 | T34: =IF(F34="","",AVERAGE(F25:F34)) -> 84.774599 | U34: =IF(G34="","",AVERAGE(G25:G34)) -> 8.1968532 | V34: =IF(E34="","",AVERAGE(E15:E34)) -> 72.389127 | W34: =IF(F34="","",AVERAGE(F15:F34)) -> 84.968895 | X34: =IF(G34="","",AVERAGE(G15:G34)) -> 8.2700112
A35: =IF(B35<>"",ROW()-2,"") -> 33 | B35: 45035.901 | C35: 1 | D35: 3 | E35: 69.662921 | F35: 84.306067 | G35: 8.988764 | H35: 74.157303 | I35: 88.452472 | J35: 7.8651685 | K35: 67.41573 | L35: 83.166517 | M35: 12.359551 | N35: 89 | O35: ⓝLuckyJ(+61.3)jun6696(-0.6)餅ちゃん(-22.0)xxxb(-38.7) | P35: https://naga.dmv.nico/htmls/845d95d8c25c7434c910e39d9bbd1fb80eee354ffc1198172554336b40123961v2_2.html?tw=3 | Q35: https://tenhou.net/4/?log=2023042010gm-0009-0000-9ff1b8f2&tw=3 | S35: =IF(E35="","",AVERAGE(E26:E35)) -> 72.968223 | T35: =IF(F35="","",AVERAGE(F26:F35)) -> 85.097962 | U35: =IF(G35="","",AVERAGE(G26:G35)) -> 7.9575183 | V35: =IF(E35="","",AVERAGE(E16:E35)) -> 72.205607 | W35: =IF(F35="","",AVERAGE(F16:F35)) -> 84.848431 | X35: =IF(G35="","",AVERAGE(G16:G35)) -> 8.3861161
A36: =IF(B36<>"",ROW()-2,"") -> 34 | B36: 45035.92 | C36: 3 | D36: 3 | E36: 72.340426 | F36: 84.613191 | G36: 4.2553191 | H36: 70.212766 | I36: 81.202766 | J36: 8.5106383 | K36: 65.957447 | L36: 79.601277 | M36: 10.638298 | N36: 47 | O36: 満貫猿(+55.0)SHOTA-IG(+22.7)ⓝLuckyJ(-16.6)ukukhide(-61.1) | P36: https://naga.dmv.nico/htmls/7f1d40e70daf7f849f2b7dde17804723cde4fbe40e3ff5b95b8d98810e2bfdc6v2_2.html?tw=3 | Q36: https://tenhou.net/4/?log=2023042011gm-0009-0000-31331971&tw=3 | S36: =IF(E36="","",AVERAGE(E27:E36)) -> 73.219507 | T36: =IF(F36="","",AVERAGE(F27:F36)) -> 85.205505 | U36: =IF(G36="","",AVERAGE(G27:G36)) -> 7.3485674 | V36: =IF(E36="","",AVERAGE(E17:E36)) -> 72.282805 | W36: =IF(F36="","",AVERAGE(F17:F36)) -> 84.890604 | X36: =IF(G36="","",AVERAGE(G17:G36)) -> 8.0679086
A37: =IF(B37<>"",ROW()-2,"") -> 35 | B37: 45035.928 | C37: 3 | D37: 3 | E37: 86.075949 | F37: 91.311392 | G37: 6.3291139 | H37: 87.341772 | I37: 92.437848 | J37: 6.3291139 | K37: 86.075949 | L37: 92.15962 | M37: 5.0632911 | N37: 79 | O37: 神様最高(+47.6)迩冬(+13.5)ⓝLuckyJ(-7.8)ハニワOcO(-53.3) | P37: https://naga.dmv.nico/htmls/73e9c55ae281d02220d306a6611022d8d3aee64d0043e3ca37f2e2e4244c92e3v2_2.html?tw=3 | Q37: https://tenhou.net/4/?log=2023042011gm-0009-0000-810729ef&tw=3 | S37: =IF(E37="","",AVERAGE(E28:E37)) -> 74.180043 | T37: =IF(F37="","",AVERAGE(F28:F37)) -> 85.698651 | U37: =IF(G37="","",AVERAGE(G28:G37)) -> 7.2461847 | V37: =IF(E37="","",AVERAGE(E18:E37)) -> 72.518806 | W37: =IF(F37="","",AVERAGE(F18:F37)) -> 85.090945 | X37: =IF(G37="","",AVERAGE(G18:G37)) -> 8.130127
... A51: =IF(B51<>"",ROW()-2,"") -> 49 | B51: 45036.235 | C51: 2 | D51: 0 | E51: 74.074074 | F51: 84.362222 | G51: 11.851852 | H51: 71.111111 | I51: 84.429333 | J51: 10.37037 | K51: 70.37037 | L51: 83.432593 | M51: 11.111111 | N51: 135 | O51: リーチまける(+51.9)ⓝLuckyJ(+13.3)りえこさま(-21.6)なつみゆ(-43.6) | P51: https://naga.dmv.nico/htmls/4667deb620baaff35213bad07695ee089ff9e7306eda2398c4e836bd7a70cc13v2_2.html?tw=0 | Q51: https://tenhou.net/4/?log=2023042018gm-0089-0000-05b20c20&tw=0 | S51: =IF(E51="","",AVERAGE(E42:E51)) -> 76.028931 | T51: =IF(F51="","",AVERAGE(F42:F51)) -> 85.912113 | U51: =IF(G51="","",AVERAGE(G42:G51)) -> 8.468923 | V51: =IF(E51="","",AVERAGE(E32:E51)) -> 76.204721 | W51: =IF(F51="","",AVERAGE(F32:F51)) -> 86.560317 | X51: =IF(G51="","",AVERAGE(G32:G51)) -> 8.0055155
A52: =IF(B52<>"",ROW()-2,"") -> 50 | B52: 45036.257 | C52: 3 | D52: 2 | E52: 78.625954 | F52: 86.717939 | G52: 6.870229 | H52: 77.099237 | I52: 88.307328 | J52: 6.1068702 | K52: 75.572519 | L52: 85.407176 | M52: 10.687023 | N52: 131 | O52: アイマ(+54.4)スカーレモン(+10.6)ⓝLuckyJ(-11.9)迷走太(-53.1) | P52: https://naga.dmv.nico/htmls/2a62b5da8979f614ab4abc804707178e2f054b5ae543a417b020ea14573cdb8dv2_2.html?tw=2 | Q52: https://tenhou.net/4/?log=2023042019gm-0089-0000-c9dd2c5a&tw=2 | S52: =IF(E52="","",AVERAGE(E43:E52)) -> 76.113748 | T52: =IF(F52="","",AVERAGE(F43:F52)) -> 85.93863 | U52: =IF(G52="","",AVERAGE(G43:G52)) -> 8.267057 | V52: =IF(E52="","",AVERAGE(E33:E52)) -> 76.849306 | W52: =IF(F52="","",AVERAGE(F33:F52)) -> 86.758266 | X52: =IF(G52="","",AVERAGE(G33:G52)) -> 7.7895864 | Y52: =IF(E52="","",AVERAGE(E3:E52)) -> 74.138495 | Z52: =IF(F52="","",AVERAGE(F3:F52)) -> 85.629268 | AA52: =IF(G52="","",AVERAGE(G3:G52)) -> 8.3500003
A53: =IF(B53<>"",ROW()-2,"") -> 51 | B53: 45036.28 | C53: 4 | D53: 2 | E53: 72.666667 | F53: 85.419267 | G53: 7.3333333 | H53: 76.666667 | I53: 86.946133 | J53: 6.6666667 | K53: 74 | L53: 84.940933 | M53: 9.3333333 | N53: 150 | O53: すずぴ(+52.4)zzz11111(+10.0)清水文(-18.5)ⓝLuckyJ(-43.9) | P53: https://naga.dmv.nico/htmls/05bc081ca28e7c7371b5c1faadc22d34bfed77ff469b0eaf0784d97b8bd1c646v2_2.html?tw=2 | Q53: https://tenhou.net/4/?log=2023042019gm-0089-0000-dc112820&tw=2 | S53: =IF(E53="","",AVERAGE(E44:E53)) -> 75.497203 | T53: =IF(F53="","",AVERAGE(F44:F53)) -> 86.02114 | U53: =IF(G53="","",AVERAGE(G44:G53)) -> 8.0514852 | V53: =IF(E53="","",AVERAGE(E34:E53)) -> 76.841862 | W53: =IF(F53="","",AVERAGE(F34:F53)) -> 86.788788 | X53: =IF(G53="","",AVERAGE(G34:G53)) -> 7.8164472 | Y53: =IF(E53="","",AVERAGE(E4:E53)) -> 74.091829 | Z53: =IF(F53="","",AVERAGE(F4:F53)) -> 85.639898 | AA53: =IF(G53="","",AVERAGE(G4:G53)) -> 8.2823812
...

Sheet Suphx Last 100
A1: # | B1: Date | C1: Rank | D1: Match | E1: Rating | F1: Bad | G1: Moves | H1: Report | I1: Paifu | J1: Last 10 | K1: Last 10 | L1: Last 10 | M1: Last 20 | N1: Last 20 | O1: Last 20 | P1: Last 50 | Q1: Last 50 | R1: Last 50 | S1: Last 100 | T1: Last 100 | U1: Last 100 | V1: Last 200 | W1: Last 200 | X1: Last 200
A2: =IF(B2<>"",ROW()-1,"") -> 1 | B2: 44438 | C2: 2 | D2: 70.833333 | E2: 84.618631 | F2: 8.3333333 | G2: 168 | H2: https://naga.dmv.nico/htmls/5280191080b7fb54dca9491ca550f5e0e4984fe06f3de385ca54665a6627ce8av2_2.html?tw=0 | I2: https://tenhou.net/4/?log=2021083013gm-0029-0000-c203d17c&tw=0 | Z2: Rank | AB2: # | AC2: Match % | AD2: Rating | AE2: Bad %
A3: =IF(B3<>"",ROW()-1,"") -> 2 | B3: 44438 | C3: 3 | D3: 77.52809 | E3: 87.876292 | F3: 5.6179775 | G3: 178 | H3: https://naga.dmv.nico/htmls/0371a7de1a09c82ca95cc76aa78732f776c166ce8dc12f2a99a7d59a4afc84fdv2_2.html?tw=3 | I3: https://tenhou.net/4/?log=2021083013gm-0029-0000-dfce9f60&tw=3 | Z3: 1 | AA3: =AB3/SUM(AB3:AB6) -> 0.24 | AB3: =COUNTIFS('Suphx Last 100'!C:C,1) -> 24 | AC3: =SUMIF('Suphx Last 100'!C:C,1,'Suphx Last 100'!D:D)/COUNTIFS('Suphx Last 100'!C:C,1,'Suphx Last 100'!D:D,"<>") -> 73.926395 | AD3: =SUMIF('Suphx Last 100'!C:C,1,'Suphx Last 100'!E:E)/COUNTIFS('Suphx Last 100'!C:C,1,'Suphx Last 100'!E:E,"<>") -> 85.81852 | AE3: =SUMIF('Suphx Last 100'!C:C,1,'Suphx Last 100'!F:F)/COUNTIFS('Suphx Last 100'!C:C,1,'Suphx Last 100'!F:F,"<>") -> 8.2813878
A4: =IF(B4<>"",ROW()-1,"") -> 3 | B4: 44438 | C4: 1 | D4: 77.358491 | E4: 87.937484 | F4: 6.2893082 | G4: 159 | H4: https://naga.dmv.nico/htmls/a8365ead44de160de115c415acd9d27b81a0d62d2d1c75470126da458c334b22v2_2.html?tw=3 | I4: https://tenhou.net/4/?log=2021083014gm-0029-0000-735bf600&tw=3 | Z4: 2 | AA4: =AB4/SUM(AB3:AB6) -> 0.34 | AB4: =COUNTIFS('Suphx Last 100'!C:C,2) -> 34 | AC4: =SUMIF('Suphx Last 100'!C:C,2,'Suphx Last 100'!D:D)/COUNTIFS('Suphx Last 100'!C:C,2,'Suphx Last 100'!D:D,"<>") -> 73.476569 | AD4: =SUMIF('Suphx Last 100'!C:C,2,'Suphx Last 100'!E:E)/COUNTIFS('Suphx Last 100'!C:C,2,'Suphx Last 100'!E:E,"<>") -> 85.901519 | AE4: =SUMIF('Suphx Last 100'!C:C,2,'Suphx Last 100'!F:F)/COUNTIFS('Suphx Last 100'!C:C,2,'Suphx Last 100'!F:F,"<>") -> 7.6382745
A5: =IF(B5<>"",ROW()-1,"") -> 4 | B5: 44438 | C5: 3 | D5: 79.166667 | E5: 90.410417 | F5: 8.3333333 | G5: 24 | H5: https://naga.dmv.nico/htmls/adbd55342e00b58080e1c3c72008609f8fe127399f18aeab882b101a04465ee5v2_2.html?tw=3 | I5: https://tenhou.net/4/?log=2021083015gm-0029-0000-2dfcbbc4&tw=3 | Z5: 3 | AA5: =AB5/SUM(AB3:AB6) -> 0.16 | AB5: =COUNTIFS('Suphx Last 100'!C:C,3) -> 16 | AC5: =SUMIF('Suphx Last 100'!C:C,3,'Suphx Last 100'!D:D)/COUNTIFS('Suphx Last 100'!C:C,3,'Suphx Last 100'!D:D,"<>") -> 73.793485 | AD5: =SUMIF('Suphx Last 100'!C:C,3,'Suphx Last 100'!E:E)/COUNTIFS('Suphx Last 100'!C:C,3,'Suphx Last 100'!E:E,"<>") -> 86.590357 | AE5: =SUMIF('Suphx Last 100'!C:C,3,'Suphx Last 100'!F:F)/COUNTIFS('Suphx Last 100'!C:C,3,'Suphx Last 100'!F:F,"<>") -> 6.9750194
A6: =IF(B6<>"",ROW()-1,"") -> 5 | B6: 44438 | C6: 2 | D6: 78.182 | E6: 88.083 | F6: 6.364 | G6: 110 | H6: https://naga.dmv.nico/htmls/3cb5ea080466e766a7a5f998cc0da8621479b20a16c10b52acbfc0a92234c11dv2_2.html?tw=0 | I6: https://tenhou.net/4/?log=2021083015gm-0029-0000-2b3c828e&tw=0 | Z6: 4 | AA6: =AB6/SUM(AB3:AB6) -> 0.26 | AB6: =COUNTIFS('Suphx Last 100'!C:C,4) -> 26 | AC6: =SUMIF('Suphx Last 100'!C:C,4,'Suphx Last 100'!D:D)/COUNTIFS('Suphx Last 100'!C:C,4,'Suphx Last 100'!D:D,"<>") -> 76.273411 | AD6: =SUMIF('Suphx Last 100'!C:C,4,'Suphx Last 100'!E:E)/COUNTIFS('Suphx Last 100'!C:C,4,'Suphx Last 100'!E:E,"<>") -> 87.07735 | AE6: =SUMIF('Suphx Last 100'!C:C,4,'Suphx Last 100'!F:F)/COUNTIFS('Suphx Last 100'!C:C,4,'Suphx Last 100'!F:F,"<>") -> 6.6246002
A7: =IF(B7<>"",ROW()-1,"") -> 6 | B7: 44438 | C7: 2 | D7: 70.588 | E7: 85.901 | F7: 8.824 | G7: 102 | H7: https://naga.dmv.nico/htmls/ae4bcb31725362c7ca3a0e6bb37d2039c6c7e990e40f48e25175a7b3dd093b37v2_2.html?tw=2 | I7: https://tenhou.net/4/?log=2021083015gm-0029-0000-50bfad7a&tw=2
A8: =IF(B8<>"",ROW()-1,"") -> 7 | B8: 44438 | C8: 1 | D8: 79.825 | E8: 90.017 | F8: 1.754 | G8: 114 | H8: https://naga.dmv.nico/htmls/40e69c543326a58400281f9db814308dcbcc717d9dc5521e8efd185d2dec7f01v2_2.html?tw=0 | I8: https://tenhou.net/4/?log=2021083016gm-0029-0000-1096b01a&tw=0 | Z8: Player | AA8: ⓝSuphx
A9: =IF(B9<>"",ROW()-1,"") -> 8 | B9: 44438 | C9: 2 | D9: 68.468 | E9: 81.953 | F9: 13.514 | G9: 111 | H9: https://naga.dmv.nico/htmls/c0241186a97f1371678c545c234d0db2158d4b89bf1786022530398db7070466v2_2.html?tw=1 | I9: https://tenhou.net/4/?log=2021083016gm-0029-0000-3f2588d5&tw=1 | Z9: Avg Rank | AA9: =(1*AB3+2*AB4+3*AB5+4*AB6)/SUM(AB3:AB6) -> 2.44
A10: =IF(B10<>"",ROW()-1,"") -> 9 | B10: 44438 | C10: 2 | D10: 68.293 | E10: 82.513 | F10: 9.756 | G10: 82 | H10: https://naga.dmv.nico/htmls/1fbcf40726e0294d103a769f9dd7f27cb1ba869f599922e05633d8b3125aac77v2_2.html?tw=2 | I10: https://tenhou.net/4/?log=2021083017gm-0029-0000-6213c21c&tw=2 | Z10: Games | AA10: =SUM(AB3:AB6) -> 100 | AC10: Lowest | AD10: Highest | AF10: Month | AG10: 44440 | AH10: 44409
A11: =IF(B11<>"",ROW()-1,"") -> 10 | B11: 44438 | C11: 3 | D11: 67.391 | E11: 83.121 | F11: 6.522 | G11: 138 | H11: https://naga.dmv.nico/htmls/94127c78bca314a7a3eb2c838807a4691d4cc7c282d635772f94baeb1f255b91v2_2.html?tw=0 | I11: https://tenhou.net/4/?log=2021083017gm-0029-0000-1fe59fcf&tw=0 | J11: =IF(D11="","",AVERAGE(D2:D11)) -> 73.763358 | K11: =IF(E11="","",AVERAGE(E2:E11)) -> 86.243082 | L11: =IF(F11="","",AVERAGE(F2:F11)) -> 7.5307952 | Z11: Avg Match % | AA11: =AVERAGE('Suphx Last 100'!D:D) -> 74.362413 | AC11: =min(D:D) -> 64.789 | AD11: =max(D:D) -> 83.537 | AF11: Rating | AG11: =AVERAGEIFS($E2:$E101,$B2:$B101,">="&AG10,$B2:$B101,"<="&EOMONTH(AG10,0)) -> 86.740502 | AH11: =AVERAGEIFS($E2:$E101,$B2:$B101,">="&AH10,$B2:$B101,"<="&EOMONTH(AH10,0)) -> 85.976756
A12: =IF(B12<>"",ROW()-1,"") -> 11 | B12: 44438 | C12: 2 | D12: 68.148 | E12: 85.53 | F12: 4.444 | G12: 135 | H12: https://naga.dmv.nico/htmls/b6e22e31562279f71b29bcbda564030405b04f3e2d3eeeff91da0863de6ef8a2v2_2.html?tw=1 | I12: https://tenhou.net/4/?log=2021083017gm-0029-0000-07d6d417&tw=1 | J12: =IF(D12="","",AVERAGE(D3:D12)) -> 73.494825 | K12: =IF(E12="","",AVERAGE(E3:E12)) -> 86.334219 | L12: =IF(F12="","",AVERAGE(F3:F12)) -> 7.1418619 | Z12: Avg Rating | AA12: =AVERAGE('Suphx Last 100'!E:E) -> 86.297529 | AC12: =min(E:E) -> 77.646 | AD12: =max(E:E) -> 91.33 | AF12: Bad % | AG12: =AVERAGEIFS($F2:$F101,$B2:$B101,">="&AG10,$B2:$B101,"<="&EOMONTH(AG10,0)) -> 7.1246573 | AH12: =AVERAGEIFS($F2:$F101,$B2:$B101,">="&AH10,$B2:$B101,"<="&EOMONTH(AH10,0)) -> 7.6389475
A13: =IF(B13<>"",ROW()-1,"") -> 12 | B13: 44438 | C13: 2 | D13: 82.036 | E13: 89.594 | F13: 7.186 | G13: 167 | H13: https://naga.dmv.nico/htmls/5d3037c1ba4a92ad959309ac740574c94ee45111cc67485e33619dec215980a2v2_2.html?tw=1 | I13: https://tenhou.net/4/?log=2021083018gm-0029-0000-01895429&tw=1 | J13: =IF(D13="","",AVERAGE(D4:D13)) -> 73.945616 | K13: =IF(E13="","",AVERAGE(E4:E13)) -> 86.50599 | L13: =IF(F13="","",AVERAGE(F4:F13)) -> 7.2986642 | Z13: Avg Bad % | AA13: =AVERAGE('Suphx Last 100'!F:F) -> 7.4229456 | AC13: =min(F:F) -> 1.754 | AD13: =max(F:F) -> 14.198 | AF13: Games | AG13: =COUNTIFS($B2:$B101,">="&AG10,$B2:$B101,"<="&EOMONTH(AG10,0)) -> 42 | AH13: =COUNTIFS($B2:$B101,">="&AH10,$B2:$B101,"<="&EOMONTH(AH10,0)) -> 58
A14: =IF(B14<>"",ROW()-1,"") -> 13 | B14: 44438 | C14: 2 | D14: 79.661 | E14: 88.985 | F14: 8.475 | G14: 59 | H14: https://naga.dmv.nico/htmls/1333e23c2d474328e8c06c4e1534c592459449588d36177ebc1a88114456466bv2_2.html?tw=3 | I14: https://tenhou.net/4/?log=2021083019gm-0029-0000-27d7aab8&tw=3 | J14: =IF(D14="","",AVERAGE(D14)) -> 79.661 | K14: =IF(E14="","",AVERAGE(E14)) -> 88.985 | L14: =IF(F14="","",AVERAGE(F14)) -> 8.475 | Z14: Avg Moves | AA14: =AVERAGE('Suphx Last 100'!G:G) -> 120.42 | AC14: =min(G:G) -> 22 | AD14: =max(G:G) -> 216
A15: =IF(B15<>"",ROW()-1,"") -> 14 | B15: 44438 | C15: 3 | D15: 79.646 | E15: 88.682 | F15: 6.195 | G15: 113 | H15: https://naga.dmv.nico/htmls/23c0b1185e39de20399d6f9e5687a36e69c80e2e04bc7182c4485876cb5962d3v2_2.html?tw=3 | I15: https://tenhou.net/4/?log=2021083019gm-0029-0000-c650e504&tw=3 | J15: =IF(D15="","",AVERAGE(D14:D15)) -> 79.6535 | K15: =IF(E15="","",AVERAGE(E14:E15)) -> 88.8335 | L15: =IF(F15="","",AVERAGE(F14:F15)) -> 7.335
A16: =IF(B16<>"",ROW()-1,"") -> 15 | B16: 44438 | C16: 2 | D16: 66.337 | E16: 81.597 | F16: 9.901 | G16: 101 | H16: https://naga.dmv.nico/htmls/10fce14e624ce9d80a56032af54ae700664202d546e39a85e28794924424bcb6v2_2.html?tw=0 | I16: https://tenhou.net/4/?log=2021083019gm-0029-0000-7daf4a10&tw=0 | J16: =IF(D16="","",AVERAGE(D14:D16)) -> 75.214667 | K16: =IF(E16="","",AVERAGE(E14:E16)) -> 86.421333 | L16: =IF(F16="","",AVERAGE(F14:F16)) -> 8.1903333
A17: =IF(B17<>"",ROW()-1,"") -> 16 | B17: 44438 | C17: 1 | D17: 74.453 | E17: 87.382 | F17: 8.029 | G17: 137 | H17: https://naga.dmv.nico/htmls/6c642a028ba870d33285eef7aeb2efae4c4e176f37917bc50184087851ed78b0v2_2.html?tw=1 | I17: https://tenhou.net/4/?log=2021083020gm-0029-0000-c80ed09f&tw=1 | J17: =IF(D17="","",AVERAGE(D14:D17)) -> 75.02425 | K17: =IF(E17="","",AVERAGE(E14:E17)) -> 86.6615 | L17: =IF(F17="","",AVERAGE(F14:F17)) -> 8.15
A18: =IF(B18<>"",ROW()-1,"") -> 17 | B18: 44438 | C18: 1 | D18: 80 | E18: 90.485 | F18: 2.857 | G18: 70 | H18: https://naga.dmv.nico/htmls/46a03ebce434b62f59efd96f10fac888f9c178ef41bbd84bd8ca32e7c60bae27v2_2.html?tw=3 | I18: https://tenhou.net/4/?log=2021083020gm-0029-0000-e1c1e40f&tw=3 | J18: =IF(D18="","",AVERAGE(D14:D18)) -> 76.0194 | K18: =IF(E18="","",AVERAGE(E14:E18)) -> 87.4262 | L18: =IF(F18="","",AVERAGE(F14:F18)) -> 7.0914
A19: =IF(B19<>"",ROW()-1,"") -> 18 | B19: 44438 | C19: 2 | D19: 77.869 | E19: 87.787 | F19: 5.738 | G19: 122 | H19: https://naga.dmv.nico/htmls/8c07b5090ca55c0a1ad51e785895415781021e3169bf93d6e31bae65dd3ac84dv2_2.html?tw=2 | I19: https://tenhou.net/4/?log=2021083021gm-0029-0000-09dec620&tw=2 | J19: =IF(D19="","",AVERAGE(D14:D19)) -> 76.327667 | K19: =IF(E19="","",AVERAGE(E14:E19)) -> 87.486333 | L19: =IF(F19="","",AVERAGE(F14:F19)) -> 6.8658333
A20: =IF(B20<>"",ROW()-1,"") -> 19 | B20: 44438 | C20: 3 | D20: 79.279 | E20: 89.76 | F20: 3.604 | G20: 111 | H20: https://naga.dmv.nico/htmls/4d5f80ccbab2fe7cc721928e751c8f8b7d66d1b1e1e0d843cecb36e204e4d921v2_2.html?tw=2 | I20: https://tenhou.net/4/?log=2021083021gm-0029-0000-785791dc&tw=2 | J20: =IF(D20="","",AVERAGE(D14:D20)) -> 76.749286 | K20: =IF(E20="","",AVERAGE(E14:E20)) -> 87.811143 | L20: =IF(F20="","",AVERAGE(F14:F20)) -> 6.3998571
A21: =IF(B21<>"",ROW()-1,"") -> 20 | B21: 44438 | C21: 1 | D21: 70.588 | E21: 82.086 | F21: 12.605 | G21: 119 | H21: https://naga.dmv.nico/htmls/8eeef225d1098c90695ce9dca1b1638a8d519ba72512b66f0f929f2acfc9cec7v2_2.html?tw=1 | I21: https://tenhou.net/4/?log=2021083022gm-0029-0000-f7f2f2fd&tw=1 | J21: =IF(D21="","",AVERAGE(D14:D21)) -> 75.979125 | K21: =IF(E21="","",AVERAGE(E14:E21)) -> 87.0955 | L21: =IF(F21="","",AVERAGE(F14:F21)) -> 7.1755
A22: =IF(B22<>"",ROW()-1,"") -> 21 | B22: 44438 | C22: 2 | D22: 76.543 | E22: 87.79 | F22: 7.407 | G22: 81 | H22: https://naga.dmv.nico/htmls/ffe5a1ff643c52e9f29d2d5fe457d585c0581ce3cfc739024b7aace9e7295547v2_2.html?tw=3 | I22: https://tenhou.net/4/?log=2021083022gm-0029-0000-cde067b2&tw=3 | J22: =IF(D22="","",AVERAGE(D14:D22)) -> 76.041778 | K22: =IF(E22="","",AVERAGE(E14:E22)) -> 87.172667 | L22: =IF(F22="","",AVERAGE(F14:F22)) -> 7.2012222 | M22: =IF(D21="","",AVERAGE(D2:D21)) -> 74.782529 | N22: =IF(E21="","",AVERAGE(E2:E21)) -> 86.715941 | O22: =IF(F21="","",AVERAGE(F2:F21)) -> 7.2170976
A23: =IF(B23<>"",ROW()-1,"") -> 22 | B23: 44438 | C23: 1 | D23: 75.155 | E23: 87.024 | F23: 4.348 | G23: 161 | H23: https://naga.dmv.nico/htmls/a3f7bd8a31799e229374769ada85c2fd08305c77c81945b4f33a1030f08997dav2_2.html?tw=0 | I23: https://tenhou.net/4/?log=2021083022gm-0029-0000-ea068aed&tw=0 | J23: =IF(D23="","",AVERAGE(D14:D23)) -> 75.9531 | K23: =IF(E23="","",AVERAGE(E14:E23)) -> 87.1578 | L23: =IF(F23="","",AVERAGE(F14:F23)) -> 6.9159 | M23: =IF(D22="","",AVERAGE(D3:D22)) -> 75.068012 | N23: =IF(E22="","",AVERAGE(E3:E22)) -> 86.87451 | O23: =IF(F22="","",AVERAGE(F3:F22)) -> 7.170781
A24: =IF(B24<>"",ROW()-1,"") -> 23 | B24: 44438 | C24: 1 | D24: 78 | E24: 85.682 | F24: 14 | G24: 100 | H24: https://naga.dmv.nico/htmls/a3fb993e0c0f84ee36660ef00b7ea337dcf427c64b46899ec36149c4870787eav2_2.html?tw=2 | I24: https://tenhou.net/4/?log=2021083023gm-0029-0000-535f4ebe&tw=2 | J24: =IF(D24="","",AVERAGE(D15:D24)) -> 75.787 | K24: =IF(E24="","",AVERAGE(E15:E24)) -> 86.8275 | L24: =IF(F24="","",AVERAGE(F15:F24)) -> 7.4684 | M24: =IF(D23="","",AVERAGE(D4:D23)) -> 74.949358 | N24: =IF(E23="","",AVERAGE(E4:E23)) -> 86.831895 | O24: =IF(F23="","",AVERAGE(F4:F23)) -> 7.1072821
A25: =IF(B25<>"",ROW()-1,"") -> 24 | B25: 44438 | C25: 4 | D25: 82.4 | E25: 91.18 | F25: 3.2 | G25: 125 | H25: https://naga.dmv.nico/htmls/ad00a939a2eb8e7ff3ccc3383d6d314e6947627de3d6fc1cee7357c60a240e61v2_2.html?tw=1 | I25: https://tenhou.net/4/?log=2021083023gm-0029-0000-0aa72d34&tw=1 | J25: =IF(D25="","",AVERAGE(D16:D25)) -> 76.0624 | K25: =IF(E25="","",AVERAGE(E16:E25)) -> 87.0773 | L25: =IF(F25="","",AVERAGE(F16:F25)) -> 7.1689 | M25: =IF(D24="","",AVERAGE(D5:D24)) -> 74.981433 | N25: =IF(E24="","",AVERAGE(E5:E24)) -> 86.719121 | O25: =IF(F24="","",AVERAGE(F5:F24)) -> 7.4928167
A26: =IF(B26<>"",ROW()-1,"") -> 25 | B26: 44439 | C26: 4 | D26: 77.941 | E26: 87.672 | F26: 4.412 | G26: 136 | H26: https://naga.dmv.nico/htmls/21bc661808db83d3337d9fa0d80b72f115f67c74b8c6caaa6d3e81057e4725dcv2_2.html?tw=3 | I26: https://tenhou.net/4/?log=2021083100gm-0029-0000-dd6f2c0f&tw=3 | J26: =IF(D26="","",AVERAGE(D17:D26)) -> 77.2228 | K26: =IF(E26="","",AVERAGE(E17:E26)) -> 87.6848 | L26: =IF(F26="","",AVERAGE(F17:F26)) -> 6.62 | M26: =IF(D25="","",AVERAGE(D6:D25)) -> 75.1431 | N26: =IF(E25="","",AVERAGE(E6:E25)) -> 86.7576 | O26: =IF(F25="","",AVERAGE(F6:F25)) -> 7.23615
A27: =IF(B27<>"",ROW()-1,"") -> 26 | B27: 44439 | C27: 4 | D27: 75.532 | E27: 85.693 | F27: 4.255 | G27: 94 | H27: https://naga.dmv.nico/htmls/eff4dcac20c4d300737120a4e5f2786a1e7e3ce7324e03a9b6dfe0ac02d2c06cv2_2.html?tw=2 | I27: https://tenhou.net/4/?log=2021083109gm-0029-0000-197a361c&tw=2 | J27: =IF(D27="","",AVERAGE(D18:D27)) -> 77.3307 | K27: =IF(E27="","",AVERAGE(E18:E27)) -> 87.5159 | L27: =IF(F27="","",AVERAGE(F18:F27)) -> 6.2426 | M27: =IF(D26="","",AVERAGE(D7:D26)) -> 75.13105 | N27: =IF(E26="","",AVERAGE(E7:E26)) -> 86.73705 | O27: =IF(F26="","",AVERAGE(F7:F26)) -> 7.13855
A28: =IF(B28<>"",ROW()-1,"") -> 27 | B28: 44439 | C28: 2 | D28: 64.865 | E28: 78.623 | F28: 6.757 | G28: 74 | H28: https://naga.dmv.nico/htmls/f4d67402460a4310bbf68eff390b4e6a6465f206abb91907eb15832573592ee1v2_2.html?tw=3 | I28: https://tenhou.net/4/?log=2021083109gm-0029-0000-97de75b0&tw=3 | J28: =IF(D28="","",AVERAGE(D19:D28)) -> 75.8172 | K28: =IF(E28="","",AVERAGE(E19:E28)) -> 86.3297 | L28: =IF(F28="","",AVERAGE(F19:F28)) -> 6.6326 | M28: =IF(D27="","",AVERAGE(D8:D27)) -> 75.37825 | N28: =IF(E27="","",AVERAGE(E8:E27)) -> 86.72665 | O28: =IF(F27="","",AVERAGE(F8:F27)) -> 6.9101
A29: =IF(B29<>"",ROW()-1,"") -> 28 | B29: 44439 | C29: 4 | D29: 72.941 | E29: 85.222 | F29: 10.588 | G29: 85 | H29: https://naga.dmv.nico/htmls/6e1f825919db8d25406442936cf11ba2a817729925366dac8c3f1a652d4bd560v2_2.html?tw=2 | I29: https://tenhou.net/4/?log=2021083109gm-0029-0000-c3a12ffa&tw=2 | J29: =IF(D29="","",AVERAGE(D20:D29)) -> 75.3244 | K29: =IF(E29="","",AVERAGE(E20:E29)) -> 86.0732 | L29: =IF(F29="","",AVERAGE(F20:F29)) -> 7.1176 | M29: =IF(D28="","",AVERAGE(D9:D28)) -> 74.63025 | N29: =IF(E28="","",AVERAGE(E9:E28)) -> 86.15695 | O29: =IF(F28="","",AVERAGE(F9:F28)) -> 7.16025
A30: =IF(B30<>"",ROW()-1,"") -> 29 | B30: 44439 | C30: 3 | D30: 71.233 | E30: 86.026 | F30: 6.164 | G30: 146 | H30: https://naga.dmv.nico/htmls/47216f6162aae49c6f30ad11b84b6e40f59d106cbf930b1851f0943954ae54f2v2_2.html?tw=3 | I30: https://tenhou.net/4/?log=2021083110gm-0029-0000-96ad310b&tw=3 | J30: =IF(D30="","",AVERAGE(D21:D30)) -> 74.5198 | K30: =IF(E30="","",AVERAGE(E21:E30)) -> 85.6998 | L30: =IF(F30="","",AVERAGE(F21:F30)) -> 7.3736 | M30: =IF(D29="","",AVERAGE(D10:D29)) -> 74.8539 | N30: =IF(E29="","",AVERAGE(E10:E29)) -> 86.3204 | O30: =IF(F29="","",AVERAGE(F10:F29)) -> 7.01395
A31: =IF(B31<>"",ROW()-1,"") -> 30 | B31: 44439 | C31: 4 | D31: 77.119 | E31: 87.467 | F31: 6.78 | G31: 118 | H31: https://naga.dmv.nico/htmls/ba974025752c141e0f9d14052fa01895cabc4fa09a1e037cee076aeb5abd9bbcv2_2.html?tw=2 | I31: https://tenhou.net/4/?log=2021083110gm-0029-0000-ebb47e9c&tw=2 | J31: =IF(D31="","",AVERAGE(D22:D31)) -> 75.1729 | K31: =IF(E31="","",AVERAGE(E22:E31)) -> 86.2379 | L31: =IF(F31="","",AVERAGE(F22:F31)) -> 6.7911 | M31: =IF(D30="","",AVERAGE(D11:D30)) -> 75.0009 | N31: =IF(E30="","",AVERAGE(E11:E30)) -> 86.49605 | O31: =IF(F30="","",AVERAGE(F11:F30)) -> 6.83435
A32: =IF(B32<>"",ROW()-1,"") -> 31 | B32: 44439 | C32: 1 | D32: 71.751 | E32: 84.555 | F32: 10.169 | G32: 177 | H32: https://naga.dmv.nico/htmls/2ac612685486832c684d9c5e402c91fbc55196d2b9c88dabe6329890a79f1598v2_2.html?tw=2 | I32: https://tenhou.net/4/?log=2021083111gm-0029-0000-4396d63c&tw=2 | J32: =IF(D32="","",AVERAGE(D23:D32)) -> 74.6937 | K32: =IF(E32="","",AVERAGE(E23:E32)) -> 85.9144 | L32: =IF(F32="","",AVERAGE(F23:F32)) -> 7.0673 | M32: =IF(D31="","",AVERAGE(D12:D31)) -> 75.4873 | N32: =IF(E31="","",AVERAGE(E12:E31)) -> 86.71335 | O32: =IF(F31="","",AVERAGE(F12:F31)) -> 6.84725
A33: =IF(B33<>"",ROW()-1,"") -> 32 | B33: 44439 | C33: 1 | D33: 64.789 | E33: 82.544 | F33: 9.155 | G33: 142 | H33: https://naga.dmv.nico/htmls/3616bea98af4f16b7dcbba891d1f074c5f26f0ea5389486d3d2c24d747f14e3cv2_2.html?tw=1 | I33: https://tenhou.net/4/?log=2021083112gm-0029-0000-3b2c7d16&tw=1 | J33: =IF(D33="","",AVERAGE(D24:D33)) -> 73.6571 | K33: =IF(E33="","",AVERAGE(E24:E33)) -> 85.4664 | L33: =IF(F33="","",AVERAGE(F24:F33)) -> 7.548 | M33: =IF(D32="","",AVERAGE(D13:D32)) -> 75.66745 | N33: =IF(E32="","",AVERAGE(E13:E32)) -> 86.6646 | O33: =IF(F32="","",AVERAGE(F13:F32)) -> 7.1335
A34: =IF(B34<>"",ROW()-1,"") -> 33 | B34: 44439 | C34: 1 | D34: 79.389 | E34: 87.544 | F34: 6.87 | G34: 131 | H34: https://naga.dmv.nico/htmls/95e9d07370d481ba225051cb01d3adec9c93eac0ab58218dbce8326e4794c594v2_2.html?tw=3 | I34: https://tenhou.net/4/?log=2021083112gm-0029-0000-5ab5abae&tw=3 | J34: =IF(D34="","",AVERAGE(D25:D34)) -> 73.796 | K34: =IF(E34="","",AVERAGE(E25:E34)) -> 85.6526 | L34: =IF(F34="","",AVERAGE(F25:F34)) -> 6.835 | M34: =IF(D33="","",AVERAGE(D14:D33)) -> 74.8051 | N34: =IF(E33="","",AVERAGE(E14:E33)) -> 86.3121 | O34: =IF(F33="","",AVERAGE(F14:F33)) -> 7.23195
... A50: =IF(B50<>"",ROW()-1,"") -> 49 | B50: 44439 | C50: 2 | D50: 68.421 | E50: 84.323 | F50: 8.421 | G50: 95 | H50: https://naga.dmv.nico/htmls/1bf3665002ac2de74f43b136ea4bb6d04c3ae4c408aa97fb66b64ac570b74bbdv2_2.html?tw=0 | I50: https://tenhou.net/4/?log=2021083120gm-0029-0000-a5619680&tw=0 | J50: =IF(D50="","",AVERAGE(D41:D50)) -> 73.3542 | K50: =IF(E50="","",AVERAGE(E41:E50)) -> 86.1044 | L50: =IF(F50="","",AVERAGE(F41:F50)) -> 8.4198 | M50: =IF(D49="","",AVERAGE(D30:D49)) -> 73.41775 | N50: =IF(E49="","",AVERAGE(E30:E49)) -> 85.8614 | O50: =IF(F49="","",AVERAGE(F30:F49)) -> 8.18415
A51: =IF(B51<>"",ROW()-1,"") -> 50 | B51: 44439 | C51: 2 | D51: 77.358 | E51: 87.223 | F51: 7.547 | G51: 106 | H51: https://naga.dmv.nico/htmls/d86d91acca37763a51dcf76cc42e860e576a5eec551b8aea17148073b8ad10d5v2_2.html?tw=1 | I51: https://tenhou.net/4/?log=2021083120gm-0029-0000-f21d93bd&tw=1 | J51: =IF(D51="","",AVERAGE(D42:D51)) -> 73.7672 | K51: =IF(E51="","",AVERAGE(E42:E51)) -> 86.0932 | L51: =IF(F51="","",AVERAGE(F42:F51)) -> 8.7021 | M51: =IF(D50="","",AVERAGE(D31:D50)) -> 73.27715 | N51: =IF(E50="","",AVERAGE(E31:E50)) -> 85.77625 | O51: =IF(F50="","",AVERAGE(F31:F50)) -> 8.297 | P51: =IF(D51="","",AVERAGE(D2:D51)) -> 74.263232 | Q51: =IF(E51="","",AVERAGE(E2:E51)) -> 86.239576 | R51: =IF(F51="","",AVERAGE(F2:F51)) -> 7.579199
A52: =IF(B52<>"",ROW()-1,"") -> 51 | B52: 44439 | C52: 3 | D52: 65.672 | E52: 77.646 | F52: 13.433 | G52: 67 | H52: https://naga.dmv.nico/htmls/cbe4549cec751a54ef3670749063764cf9664ca4b98fd1ce42f5bc2eed0cfc53v2_2.html?tw=0 | I52: https://tenhou.net/4/?log=2021083120gm-0029-0000-30b04ca1&tw=0 | J52: =IF(D52="","",AVERAGE(D43:D52)) -> 72.1166 | K52: =IF(E52="","",AVERAGE(E43:E52)) -> 84.8873 | L52: =IF(F52="","",AVERAGE(F43:F52)) -> 9.5504 | M52: =IF(D51="","",AVERAGE(D32:D51)) -> 73.2891 | N52: =IF(E51="","",AVERAGE(E32:E51)) -> 85.76405 | O52: =IF(F51="","",AVERAGE(F32:F51)) -> 8.33535 | P52: =IF(D52="","",AVERAGE(D3:D52)) -> 74.160005 | Q52: =IF(E52="","",AVERAGE(E3:E52)) -> 86.100124 | R52: =IF(F52="","",AVERAGE(F3:F52)) -> 7.6811924
A53: =IF(B53<>"",ROW()-1,"") -> 52 | B53: 44439 | C53: 2 | D53: 68.182 | E53: 83.14 | F53: 4.545 | G53: 22 | H53: https://naga.dmv.nico/htmls/04ba28aa8c7c192beba81d07ea65da883a55b26b69511745422f8a6620fb8fd2v2_2.html?tw=3 | I53: https://tenhou.net/4/?log=2021083121gm-0029-0000-e0de871a&tw=3 | J53: =IF(D53="","",AVERAGE(D44:D53)) -> 72.1906 | K53: =IF(E53="","",AVERAGE(E44:E53)) -> 85.0334 | L53: =IF(F53="","",AVERAGE(F44:F53)) -> 8.6096 | M53: =IF(D52="","",AVERAGE(D33:D52)) -> 72.98515 | N53: =IF(E52="","",AVERAGE(E33:E52)) -> 85.4186 | O53: =IF(F52="","",AVERAGE(F33:F52)) -> 8.49855 | P53: =IF(D53="","",AVERAGE(D4:D53)) -> 73.973083 | Q53: =IF(E53="","",AVERAGE(E4:E53)) -> 86.005398 | R53: =IF(F53="","",AVERAGE(F4:F53)) -> 7.6597328
A54: =IF(B54<>"",ROW()-1,"") -> 53 | B54: 44439 | C54: 1 | D54: 81.065 | E54: 88.335 | F54: 8.284 | G54: 169 | H54: https://naga.dmv.nico/htmls/1b4e01d620e1a9c7e2a8ca7acb01484ff02c1cb0e3f7229a65be556d020ec9d7v2_2.html?tw=2 | I54: https://tenhou.net/4/?log=2021083121gm-0029-0000-f03c1236&tw=2 | J54: =IF(D54="","",AVERAGE(D45:D54)) -> 72.9679 | K54: =IF(E54="","",AVERAGE(E45:E54)) -> 85.0836 | L54: =IF(F54="","",AVERAGE(F45:F54)) -> 8.8169 | M54: =IF(D53="","",AVERAGE(D34:D53)) -> 73.1548 | N54: =IF(E53="","",AVERAGE(E34:E53)) -> 85.4484 | O54: =IF(F53="","",AVERAGE(F34:F53)) -> 8.26805 | P54: =IF(D54="","",AVERAGE(D5:D54)) -> 74.047213 | Q54: =IF(E54="","",AVERAGE(E5:E54)) -> 86.013348 | R54: =IF(F54="","",AVERAGE(F5:F54)) -> 7.6996267
A55: =IF(B55<>"",ROW()-1,"") -> 54 | B55: 44439 | C55: 2 | D55: 69.136 | E55: 83.004 | F55: 8.642 | G55: 81 | H55: https://naga.dmv.nico/htmls/39b2581fb66f22311c8ce1d960b6fd4e73b9c259f6c3af212b9f5d91a77ac1e5v2_2.html?tw=1 | I55: https://tenhou.net/4/?log=2021083122gm-0029-0000-339855a8&tw=1 | J55: =IF(D55="","",AVERAGE(D46:D55)) -> 72.2656 | K55: =IF(E55="","",AVERAGE(E46:E55)) -> 84.527 | L55: =IF(F55="","",AVERAGE(F46:F55)) -> 9.0851 | M55: =IF(D54="","",AVERAGE(D35:D54)) -> 73.2386 | N55: =IF(E54="","",AVERAGE(E35:E54)) -> 85.48795 | O55: =IF(F54="","",AVERAGE(F35:F54)) -> 8.33875 | P55: =IF(D55="","",AVERAGE(D6:D55)) -> 73.8466 | Q55: =IF(E55="","",AVERAGE(E6:E55)) -> 85.86522 | R55: =IF(F55="","",AVERAGE(F6:F55)) -> 7.7058
...
